Workbook

Sheet UI
B2: Sagittal Standard Just Intonation Notation Calculator | U2: Precision Level | W2: Medium | AD2: High* | AK2: Ultra | AR2: Extreme** | AY2: Single-shaft Sagittals are Representing (¢)
U3: Maximum Symbol Set | W3: Athenian | AD3: Promethean | AK3: Herculean | AR3: Olympian
U4: Limit | W4: 17 | AD4: 23 | AK4: 23 | AR4: 47
U5: Resolution (≈¢) | W5: 5.41 | AD5: 2.42 | AK5: 1.96 | AR5: 0.49
B6: You can enter your pitch's prime factor exponents in the light-blue-colored cells. Leave 0's to ignore. | U6: Diacritics | W6: none | AD6: none | AK6: accents | AR6: accents & breves
B7: Prime: | C7: 3 | D7: 5 | E7: 7 | F7: 11 | G7: 13 | H7: 17 | I7: 19 | J7: 23 | K7: 29 | L7: 31 | M7: 37 | N7: 41 | O7: 43 | P7: 47 | Q7: 53 | R7: 59 | S7: 61 | W7: ASCII | Y7: Unicode | AA7: Fifths Count | AB7: Error (¢) | AD7: ASCII | AF7: Unicode | AH7: Fifths Count | AI7: Error (¢) | AK7: ASCII | AM7: Unicode | AO7: Fifths Count | AP7: Error (¢) | AR7: ASCII | AT7: Unicode | AV7: Fifths Count | AW7: Error (¢)
B8: Exponent: | C8: 0 | D8: 0 | E8: 0 | F8: 0 | G8: 0 | H8: 0 | I8: 0 | J8: 0 | K8: 0 | L8: 0 | M8: 0 | N8: 0 | O8: 0 | P8: 0 | Q8: 0 | R8: 0 | S8: 0 | W8: Evo | X8: Revo | Y8: Evo | Z8: Revo | AD8: Evo | AE8: Revo | AF8: Evo | AG8: Revo | AK8: Evo | AL8: Revo | AM8: Evo | AN8: Revo | AR8: Evo | AS8: Revo | AT8: Evo | AU8: Revo
B9: You can also directly enter your pitch as a ratio. Leave 1's to ignore. | W9: =CONCATENATE(VLOOKUP(Calculator!$H6,Key!$A$2:$E$982,2,FALSE),Calculator!$B6) | X9: =CONCATENATE(VLOOKUP(Calculator!$H6,Key!$A$2:$E$982,3,FALSE),Calculator!$B6) | Y9: =CONCATENATE(VLOOKUP(Calculator!$H6,Key!$A$2:$E$982,4,FALSE),Calculator!$C6) | Z9: =CONCATENATE(VLOOKUP(Calculator!$H6,Key!$A$2:$E$982,5,FALSE),Calculator!$C6) | AA9: =Calculator!$AB6 | AB9: =Calculator!$L6 | AD9: =CONCATENATE(VLOOKUP(Calculator!$M6,Key!$A$2:$E$982,2,FALSE),Calculator!$B6) | AE9: =CONCATENATE(VLOOKUP(Calculator!$M6,Key!$A$2:$E$982,3,FALSE),Calculator!$B6) | AF9: =CONCATENATE(VLOOKUP(Calculator!$M6,Key!$A$2:$E$982,4,FALSE),Calculator!$C6) | AG9: =CONCATENATE(VLOOKUP(Calculator!$M6,Key!$A$2:$E$982,5,FALSE),Calculator!$C6) | AH9: =Calculator!$AB6 | AI9: =Calculator!$Q6 | AK9: =CONCATENATE(VLOOKUP(Calculator!$R6,Key!$A$2:$E$982,2,FALSE),Calculator!$B6) | AL9: =CONCATENATE(VLOOKUP(Calculator!$R6,Key!$A$2:$E$982,3,FALSE),Calculator!$B6) | AM9: =CONCATENATE(VLOOKUP(Calculator!$R6,Key!$A$2:$E$982,4,FALSE),Calculator!$C6) | AN9: =CONCATENATE(VLOOKUP(Calculator!$R6,Key!$A$2:$E$982,5,FALSE),Calculator!$C6) | AO9: =Calculator!$AB6 | AP9: =Calculator!$V6 | AR9: =CONCATENATE(VLOOKUP(Calculator!$W6,Key!$A$2:$E$982,2,FALSE),Calculator!$B6) | AS9: =CONCATENATE(VLOOKUP(Calculator!$W6,Key!$A$2:$E$982,3,FALSE),Calculator!$B6) | AT9: =CONCATENATE(VLOOKUP(Calculator!$W6,Key!$A$2:$E$982,4,FALSE),Calculator!$C6) | AU9: =CONCATENATE(VLOOKUP(Calculator!$W6,Key!$A$2:$E$982,5,FALSE),Calculator!$C6) | AV9: =Calculator!$AB6 | AW9: =Calculator!$AA6 | AY9: =IF(Calculator!$G6=0,"",Calculator!$G6)
C10: 5 | F10: Numerator | M10: Your pitch is | N10: =Calculator!AG5 | P10: cents above 1/1. | W10: =CONCATENATE(VLOOKUP(Calculator!$H7,Key!$A$2:$E$982,2,FALSE),Calculator!$B7) | X10: =CONCATENATE(VLOOKUP(Calculator!$H7,Key!$A$2:$E$982,3,FALSE),Calculator!$B7) | Y10: =CONCATENATE(VLOOKUP(Calculator!$H7,Key!$A$2:$E$982,4,FALSE),Calculator!$C7) | Z10: =CONCATENATE(VLOOKUP(Calculator!$H7,Key!$A$2:$E$982,5,FALSE),Calculator!$C7) | AA10: =Calculator!$AB7 | AB10: =Calculator!$L7 | AD10: =CONCATENATE(VLOOKUP(Calculator!$M7,Key!$A$2:$E$982,2,FALSE),Calculator!$B7) | AE10: =CONCATENATE(VLOOKUP(Calculator!$M7,Key!$A$2:$E$982,3,FALSE),Calculator!$B7) | AF10: =CONCATENATE(VLOOKUP(Calculator!$M7,Key!$A$2:$E$982,4,FALSE),Calculator!$C7) | AG10: =CONCATENATE(VLOOKUP(Calculator!$M7,Key!$A$2:$E$982,5,FALSE),Calculator!$C7) | AH10: =Calculator!$AB7 | AI10: =Calculator!$Q7 | AK10: =CONCATENATE(VLOOKUP(Calculator!$R7,Key!$A$2:$E$982,2,FALSE),Calculator!$B7) | AL10: =CONCATENATE(VLOOKUP(Calculator!$R7,Key!$A$2:$E$982,3,FALSE),Calculator!$B7) | AM10: =CONCATENATE(VLOOKUP(Calculator!$R7,Key!$A$2:$E$982,4,FALSE),Calculator!$C7) | AN10: =CONCATENATE(VLOOKUP(Calculator!$R7,Key!$A$2:$E$982,5,FALSE),Calculator!$C7) | AO10: =Calculator!$AB7 | AP10: =Calculator!$V7 | AR10: =CONCATENATE(VLOOKUP(Calculator!$W7,Key!$A$2:$E$982,2,FALSE),Calculator!$B7) | AS10: =CONCATENATE(VLOOKUP(Calculator!$W7,Key!$A$2:$E$982,3,FALSE),Calculator!$B7) | AT10: =CONCATENATE(VLOOKUP(Calculator!$W7,Key!$A$2:$E$982,4,FALSE),Calculator!$C7) | AU10: =CONCATENATE(VLOOKUP(Calculator!$W7,Key!$A$2:$E$982,5,FALSE),Calculator!$C7) | AV10: =Calculator!$AB7 | AW10: =Calculator!$AA7 | AY10: =IF(Calculator!$G7=0,"",Calculator!$G7)
C11: 4 | F11: Denominator | W11: =CONCATENATE(VLOOKUP(Calculator!$H8,Key!$A$2:$E$982,2,FALSE),Calculator!$B8) | X11: =CONCATENATE(VLOOKUP(Calculator!$H8,Key!$A$2:$E$982,3,FALSE),Calculator!$B8) | Y11: =CONCATENATE(VLOOKUP(Calculator!$H8,Key!$A$2:$E$982,4,FALSE),Calculator!$C8) | Z11: =CONCATENATE(VLOOKUP(Calculator!$H8,Key!$A$2:$E$982,5,FALSE),Calculator!$C8) | AA11: =Calculator!$AB8 | AB11: =Calculator!$L8 | AD11: =CONCATENATE(VLOOKUP(Calculator!$M8,Key!$A$2:$E$982,2,FALSE),Calculator!$B8) | AE11: =CONCATENATE(VLOOKUP(Calculator!$M8,Key!$A$2:$E$982,3,FALSE),Calculator!$B8) | AF11: =CONCATENATE(VLOOKUP(Calculator!$M8,Key!$A$2:$E$982,4,FALSE),Calculator!$C8) | AG11: =CONCATENATE(VLOOKUP(Calculator!$M8,Key!$A$2:$E$982,5,FALSE),Calculator!$C8) | AH11: =Calculator!$AB8 | AI11: =Calculator!$Q8 | AK11: =CONCATENATE(VLOOKUP(Calculator!$R8,Key!$A$2:$E$982,2,FALSE),Calculator!$B8) | AL11: =CONCATENATE(VLOOKUP(Calculator!$R8,Key!$A$2:$E$982,3,FALSE),Calculator!$B8) | AM11: =CONCATENATE(VLOOKUP(Calculator!$R8,Key!$A$2:$E$982,4,FALSE),Calculator!$C8) | AN11: =CONCATENATE(VLOOKUP(Calculator!$R8,Key!$A$2:$E$982,5,FALSE),Calculator!$C8) | AO11: =Calculator!$AB8 | AP11: =Calculator!$V8 | AR11: =CONCATENATE(VLOOKUP(Calculator!$W8,Key!$A$2:$E$982,2,FALSE),Calculator!$B8) | AS11: =CONCATENATE(VLOOKUP(Calculator!$W8,Key!$A$2:$E$982,3,FALSE),Calculator!$B8) | AT11: =CONCATENATE(VLOOKUP(Calculator!$W8,Key!$A$2:$E$982,4,FALSE),Calculator!$C8) | AU11: =CONCATENATE(VLOOKUP(Calculator!$W8,Key!$A$2:$E$982,5,FALSE),Calculator!$C8) | AV11: =Calculator!$AB8 | AW11: =Calculator!$AA8 | AY11: =IF(Calculator!$G8=0,"",Calculator!$G8)
B12: Enter a Pythagorean nominal for your 1/1 (from bbF to xB). | W12: =CONCATENATE(VLOOKUP(Calculator!$H9,Key!$A$2:$E$982,2,FALSE),Calculator!$B9) | X12: =CONCATENATE(VLOOKUP(Calculator!$H9,Key!$A$2:$E$982,3,FALSE),Calculator!$B9) | Y12: =CONCATENATE(VLOOKUP(Calculator!$H9,Key!$A$2:$E$982,4,FALSE),Calculator!$C9) | Z12: =CONCATENATE(VLOOKUP(Calculator!$H9,Key!$A$2:$E$982,5,FALSE),Calculator!$C9) | AA12: =Calculator!$AB9 | AB12: =Calculator!$L9 | AD12: =CONCATENATE(VLOOKUP(Calculator!$M9,Key!$A$2:$E$982,2,FALSE),Calculator!$B9) | AE12: =CONCATENATE(VLOOKUP(Calculator!$M9,Key!$A$2:$E$982,3,FALSE),Calculator!$B9) | AF12: =CONCATENATE(VLOOKUP(Calculator!$M9,Key!$A$2:$E$982,4,FALSE),Calculator!$C9) | AG12: =CONCATENATE(VLOOKUP(Calculator!$M9,Key!$A$2:$E$982,5,FALSE),Calculator!$C9) | AH12: =Calculator!$AB9 | AI12: =Calculator!$Q9 | AK12: =CONCATENATE(VLOOKUP(Calculator!$R9,Key!$A$2:$E$982,2,FALSE),Calculator!$B9) | AL12: =CONCATENATE(VLOOKUP(Calculator!$R9,Key!$A$2:$E$982,3,FALSE),Calculator!$B9) | AM12: =CONCATENATE(VLOOKUP(Calculator!$R9,Key!$A$2:$E$982,4,FALSE),Calculator!$C9) | AN12: =CONCATENATE(VLOOKUP(Calculator!$R9,Key!$A$2:$E$982,5,FALSE),Calculator!$C9) | AO12: =Calculator!$AB9 | AP12: =Calculator!$V9 | AR12: =CONCATENATE(VLOOKUP(Calculator!$W9,Key!$A$2:$E$982,2,FALSE),Calculator!$B9) | AS12: =CONCATENATE(VLOOKUP(Calculator!$W9,Key!$A$2:$E$982,3,FALSE),Calculator!$B9) | AT12: =CONCATENATE(VLOOKUP(Calculator!$W9,Key!$A$2:$E$982,4,FALSE),Calculator!$C9) | AU12: =CONCATENATE(VLOOKUP(Calculator!$W9,Key!$A$2:$E$982,5,FALSE),Calculator!$C9) | AV12: =Calculator!$AB9 | AW12: =Calculator!$AA9 | AY12: =IF(Calculator!$G9=0,"",Calculator!$G9)
B13: 1/1 = | C13: C | W13: =CONCATENATE(VLOOKUP(Calculator!$H10,Key!$A$2:$E$982,2,FALSE),Calculator!$B10) | X13: =CONCATENATE(VLOOKUP(Calculator!$H10,Key!$A$2:$E$982,3,FALSE),Calculator!$B10) | Y13: =CONCATENATE(VLOOKUP(Calculator!$H10,Key!$A$2:$E$982,4,FALSE),Calculator!$C10) | Z13: =CONCATENATE(VLOOKUP(Calculator!$H10,Key!$A$2:$E$982,5,FALSE),Calculator!$C10) | AA13: =Calculator!$AB10 | AB13: =Calculator!$L10 | AD13: =CONCATENATE(VLOOKUP(Calculator!$M10,Key!$A$2:$E$982,2,FALSE),Calculator!$B10) | AE13: =CONCATENATE(VLOOKUP(Calculator!$M10,Key!$A$2:$E$982,3,FALSE),Calculator!$B10) | AF13: =CONCATENATE(VLOOKUP(Calculator!$M10,Key!$A$2:$E$982,4,FALSE),Calculator!$C10) | AG13: =CONCATENATE(VLOOKUP(Calculator!$M10,Key!$A$2:$E$982,5,FALSE),Calculator!$C10) | AH13: =Calculator!$AB10 | AI13: =Calculator!$Q10 | AK13: =CONCATENATE(VLOOKUP(Calculator!$R10,Key!$A$2:$E$982,2,FALSE),Calculator!$B10) | AL13: =CONCATENATE(VLOOKUP(Calculator!$R10,Key!$A$2:$E$982,3,FALSE),Calculator!$B10) | AM13: =CONCATENATE(VLOOKUP(Calculator!$R10,Key!$A$2:$E$982,4,FALSE),Calculator!$C10) | AN13: =CONCATENATE(VLOOKUP(Calculator!$R10,Key!$A$2:$E$982,5,FALSE),Calculator!$C10) | AO13: =Calculator!$AB10 | AP13: =Calculator!$V10 | AR13: =CONCATENATE(VLOOKUP(Calculator!$W10,Key!$A$2:$E$982,2,FALSE),Calculator!$B10) | AS13: =CONCATENATE(VLOOKUP(Calculator!$W10,Key!$A$2:$E$982,3,FALSE),Calculator!$B10) | AT13: =CONCATENATE(VLOOKUP(Calculator!$W10,Key!$A$2:$E$982,4,FALSE),Calculator!$C10) | AU13: =CONCATENATE(VLOOKUP(Calculator!$W10,Key!$A$2:$E$982,5,FALSE),Calculator!$C10) | AV13: =Calculator!$AB10 | AW13: =Calculator!$AA10 | AY13: =IF(Calculator!$G10=0,"",Calculator!$G10)
C14: To view the Unicode characters, you must install the Bravura font. Support for installing Bravura font can be found here: | W14: =CONCATENATE(VLOOKUP(Calculator!$H11,Key!$A$2:$E$982,2,FALSE),Calculator!$B11) | X14: =CONCATENATE(VLOOKUP(Calculator!$H11,Key!$A$2:$E$982,3,FALSE),Calculator!$B11) | Y14: =CONCATENATE(VLOOKUP(Calculator!$H11,Key!$A$2:$E$982,4,FALSE),Calculator!$C11) | Z14: =CONCATENATE(VLOOKUP(Calculator!$H11,Key!$A$2:$E$982,5,FALSE),Calculator!$C11) | AA14: =Calculator!$AB11 | AB14: =Calculator!$L11 | AD14: =CONCATENATE(VLOOKUP(Calculator!$M11,Key!$A$2:$E$982,2,FALSE),Calculator!$B11) | AE14: =CONCATENATE(VLOOKUP(Calculator!$M11,Key!$A$2:$E$982,3,FALSE),Calculator!$B11) | AF14: =CONCATENATE(VLOOKUP(Calculator!$M11,Key!$A$2:$E$982,4,FALSE),Calculator!$C11) | AG14: =CONCATENATE(VLOOKUP(Calculator!$M11,Key!$A$2:$E$982,5,FALSE),Calculator!$C11) | AH14: =Calculator!$AB11 | AI14: =Calculator!$Q11 | AK14: =CONCATENATE(VLOOKUP(Calculator!$R11,Key!$A$2:$E$982,2,FALSE),Calculator!$B11) | AL14: =CONCATENATE(VLOOKUP(Calculator!$R11,Key!$A$2:$E$982,3,FALSE),Calculator!$B11) | AM14: =CONCATENATE(VLOOKUP(Calculator!$R11,Key!$A$2:$E$982,4,FALSE),Calculator!$C11) | AN14: =CONCATENATE(VLOOKUP(Calculator!$R11,Key!$A$2:$E$982,5,FALSE),Calculator!$C11) | AO14: =Calculator!$AB11 | AP14: =Calculator!$V11 | AR14: =CONCATENATE(VLOOKUP(Calculator!$W11,Key!$A$2:$E$982,2,FALSE),Calculator!$B11) | AS14: =CONCATENATE(VLOOKUP(Calculator!$W11,Key!$A$2:$E$982,3,FALSE),Calculator!$B11) | AT14: =CONCATENATE(VLOOKUP(Calculator!$W11,Key!$A$2:$E$982,4,FALSE),Calculator!$C11) | AU14: =CONCATENATE(VLOOKUP(Calculator!$W11,Key!$A$2:$E$982,5,FALSE),Calculator!$C11) | AV14: =Calculator!$AB11 | AW14: =Calculator!$AA11 | AY14: =IF(Calculator!$G11=0,"",Calculator!$G11)
C15: http://forum.sagittal.org/viewtopic.php?f=16&t=429 | W15: =CONCATENATE(VLOOKUP(Calculator!$H12,Key!$A$2:$E$982,2,FALSE),Calculator!$B12) | X15: =CONCATENATE(VLOOKUP(Calculator!$H12,Key!$A$2:$E$982,3,FALSE),Calculator!$B12) | Y15: =CONCATENATE(VLOOKUP(Calculator!$H12,Key!$A$2:$E$982,4,FALSE),Calculator!$C12) | Z15: =CONCATENATE(VLOOKUP(Calculator!$H12,Key!$A$2:$E$982,5,FALSE),Calculator!$C12) | AA15: =Calculator!$AB12 | AB15: =Calculator!$L12 | AD15: =CONCATENATE(VLOOKUP(Calculator!$M12,Key!$A$2:$E$982,2,FALSE),Calculator!$B12) | AE15: =CONCATENATE(VLOOKUP(Calculator!$M12,Key!$A$2:$E$982,3,FALSE),Calculator!$B12) | AF15: =CONCATENATE(VLOOKUP(Calculator!$M12,Key!$A$2:$E$982,4,FALSE),Calculator!$C12) | AG15: =CONCATENATE(VLOOKUP(Calculator!$M12,Key!$A$2:$E$982,5,FALSE),Calculator!$C12) | AH15: =Calculator!$AB12 | AI15: =Calculator!$Q12 | AK15: =CONCATENATE(VLOOKUP(Calculator!$R12,Key!$A$2:$E$982,2,FALSE),Calculator!$B12) | AL15: =CONCATENATE(VLOOKUP(Calculator!$R12,Key!$A$2:$E$982,3,FALSE),Calculator!$B12) | AM15: =CONCATENATE(VLOOKUP(Calculator!$R12,Key!$A$2:$E$982,4,FALSE),Calculator!$C12) | AN15: =CONCATENATE(VLOOKUP(Calculator!$R12,Key!$A$2:$E$982,5,FALSE),Calculator!$C12) | AO15: =Calculator!$AB12 | AP15: =Calculator!$V12 | AR15: =CONCATENATE(VLOOKUP(Calculator!$W12,Key!$A$2:$E$982,2,FALSE),Calculator!$B12) | AS15: =CONCATENATE(VLOOKUP(Calculator!$W12,Key!$A$2:$E$982,3,FALSE),Calculator!$B12) | AT15: =CONCATENATE(VLOOKUP(Calculator!$W12,Key!$A$2:$E$982,4,FALSE),Calculator!$C12) | AU15: =CONCATENATE(VLOOKUP(Calculator!$W12,Key!$A$2:$E$982,5,FALSE),Calculator!$C12) | AV15: =Calculator!$AB12 | AW15: =Calculator!$AA12 | AY15: =IF(Calculator!$G12=0,"",Calculator!$G12)
C16: Standard JI notation precision levels are visualized here:
C17: http://sagittal.org/SagittalJI.gif | AD17: *This notation is not recommended. | AR17: **Note that if the ASCII above shows commas , or back-quotes `
AR18: the unicode above will not be correct
AR19: until the breves (mina diacritics) are added to the Bravura font.

Sheet Calculator
A1: bbFbbCbbGbbDbbAbbEbbBbF bC bG bD bA bE bB F C G D A E B #F #C #G #D #A #E #B xF xC xG xD xA xE xB | AD1: (in case you want to play with this) | AG1: facts about the pitch | AJ1: facts about the 1/1
A2: Full Key and Error Calculation | AD2: =(LOG(3,2)*7-11)*1200 | AE2: cents in apotome | AG2: =(3^UI!$C$8)*(5^UI!$D$8)*(7^UI!$E$8)*(11^UI!$F$8)*(13^UI!$G$8)*(17^UI!$H$8)*(19^UI!$I$8)*(23^UI!$J$8)*(29^UI!$K$8)*(31^UI!$L$8)*(37^UI!$M$8)*(41^UI!$N$8)*(43^UI!$O$8)*(47^UI!$P$8)*(53^UI!$Q$8)*(59^UI!$R$8)*(61^UI!$S$8) | AH2: monzo multiplier | AJ2: =UI!$C$8+(FIND(UI!$C$13&REPT(" ",3-LEN(UI!$C$13)),$A$1)-46)/3 | AK2: fifths above C
AD3: =Boundaries!N154+0.000000001 | AE3: cents maximum | AG3: =UI!$C$10/UI!$C$11 | AH3: ratio multiplier
A4: Nominal Base Cents | B4: Nominal (if in range) | C4: Nominal inside notehead (if in range) | D4: Sharp/Flat | E4: Sharp/Flat Key Shift | F4: Cents | G4: Alteration | H4: Medium | M4: High | R4: Ultra | W4: Extreme | AB4: Fifths above 1/1 | AD4: =AD$3/AD$2 | AE4: max./apotome | AG4: =AG2*AG3 | AH4: total multiplier
H5: Full Key | I5: Key | J5: Symbol | K5: Default Value | L5: Error | M5: Full Key | N5: Key | O5: Symbol | P5: Default Value | Q5: Error | R5: Full Key | S5: Key | T5: Symbol | U5: Default Value | V5: Error | W5: Full Key | X5: Key | Y5: Symbol | Z5: Default Value | AA5: Error | AG5: =MOD(1200*LOG(AG4,2),1200) | AH5: cents above 1/1
A6: =IF(ABS(AG$8-1200)<300,1200,0) | B6: =IF(ABS(AG$8-A6)>2.000001*AD$2,"","C") | C6: =IF(ABS(AG$8-A6)>2.000001*AD$2,""," ") | D6: =IF(B6="","",IF(AG$8-A6>$AD$2*(1+AD$4),"x",IF(AG$8-A6>AD$2*AD$4,"#",IF(A6-AG$8>AD$2*(1+AD$4),"bb",IF(A6-AG$8>AD$2*AD$4,"b",""))))) | E6: =IF(D6="x",2000,IF(D6="#",1000,IF(D6="",0,IF(D6="b",-1000,IF(D6="bb",-2000))))) | F6: =IF(B6="","",IF(AG$8-A6>AD$2*(1+AD$4),A6+AD$2*2,IF(AG$8-A6>AD$2*AD$4,A6+AD$2,IF(A6-AG$8>AD$2*(1+AD$4),A6-2*AD$2,IF(A6-AG$8>AD$2*AD$4,A6-AD$2,A6))))) | G6: =IF(B6="","",IF(ROUND(AG$8-F6,3)=0,0,AG$8-F6)) | H6: =IF($G6="",0,I6+$E6) | I6: =IF($G6="","",IF(ROUND($G6,3)=0,0,IF($G6>0,VLOOKUP($G6,Boundaries!$B$5:$C$9153,2,TRUE),-1*VLOOKUP(-1*$G6,Boundaries!$B$5:$C153,2,TRUE)))) | J6: =IF(I6="","",VLOOKUP(I6,Key!$A$2:$B$982,2,FALSE)) | K6: =IF(I6="","",IF(I6=0,"",IF(I6>0,VLOOKUP(I6,Commas!$A$2:$E$9149,5,FALSE),-1*VLOOKUP(-1*I6,Commas!$A$2:$E$9149,5,FALSE)))) | L6: =IF($B6="","",IF($G6="",0,IF(K6="",$G6,ABS($G6-K6)))) | M6: =IF($G6="",0,N6+$E6) | N6: =IF($G6="","",IF(ROUND($G6,3)=0,0,IF($G6>0,VLOOKUP($G6,Boundaries!$F$5:$G$9153,2,TRUE),-1*VLOOKUP(-1*$G6,Boundaries!$F$5:$G$9153,2,TRUE)))) | O6: =IF(N6="","",VLOOKUP(N6,Key!$A$2:$B$982,2,FALSE)) | P6: =IF(N6="","",IF(N6=0,"",IF(N6>0,VLOOKUP(N6,Commas!$A$2:$E$9149,5,FALSE),-1*VLOOKUP(-1*N6,Commas!$A$2:$E$9149,5,FALSE)))) | Q6: =IF($B6="","",IF($G6="",0,IF(P6="",$G6,ABS($G6-P6)))) | R6: =IF($G6="",0,S6+$E6) | S6: =IF($G6="","",IF(ROUND($G6,3)=0,0,IF($G6>0,VLOOKUP($G6,Boundaries!$J$5:$K$9153,2,TRUE),-1*VLOOKUP(-1*$G6,Boundaries!$J$5:$K$9153,2,TRUE)))) | T6: =IF(S6="","",VLOOKUP(S6,Key!$A$2:$B$982,2,FALSE)) | U6: =IF(S6="","",IF(S6=0,"",IF(S6>0,VLOOKUP(S6,Commas!$A$2:$E$9149,5,FALSE),-1*VLOOKUP(-1*S6,Commas!$A$2:$E$9149,5,FALSE)))) | V6: =IF($B6="","",IF($G6="",0,IF(U6="",0,ABS($G6-U6)))) | W6: =IF($G6="",0,X6+$E6) | X6: =IF($G6="","",IF(ROUND($G6,3)=0,0,IF($G6>0,VLOOKUP($G6,Boundaries!$N$5:$O$9153,2,TRUE),-1*VLOOKUP(-1*$G6,Boundaries!$N$5:$O$9153,2,TRUE)))) | Y6: =IF(X6="","",VLOOKUP(X6,Key!$A$2:$B$982,2,FALSE)) | Z6: =IF(X6="","",IF(X6=0,"",IF(X6>0,VLOOKUP(X6,Commas!$A$2:$E$9149,5,FALSE),-1*VLOOKUP(-1*X6,Commas!$A$2:$E$9149,5,FALSE)))) | AA6: =IF($B6="","",IF($G6="",0,IF(Z6="",0,ABS($G6-Z6)))) | AB6: =IF(B6<>"",UI!$C$8+(FIND(D6&B6&REPT(" ",3-LEN(D6&B6)),$A$1)-46)/3-AJ$2,"")
A7: =IF(ABS(AG$8-1200*(LN(9/8)/LN(2))-1200)<300,1200*(LN(9/8)/LN(2))+1200,1200*(LN(9/8)/LN(2))) | B7: =IF(ABS(AG$8-A7)>2.000001*AD$2,"","D") | C7: =IF(ABS(AG$8-A7)>2.000001*AD$2,""," ") | D7: =IF(B7="","",IF(AG$8-A7>AD$2*(1+AD$4),"x",IF(AG$8-A7>AD$2*AD$4,"#",IF(A7-AG$8>AD$2*(1+AD$4),"bb",IF(A7-AG$8>AD$2*AD$4,"b",""))))) | E7: =IF(D7="x",2000,IF(D7="#",1000,IF(D7="",0,IF(D7="b",-1000,IF(D7="bb",-2000))))) | F7: =IF(B7="","",IF(AG$8-A7>AD$2*(1+AD$4),A7+AD$2*2,IF(AG$8-A7>AD$2*AD$4,A7+AD$2,IF(A7-AG$8>AD$2*(1+AD$4),A7-2*AD$2,IF(A7-AG$8>AD$2*AD$4,A7-AD$2,A7))))) | G7: =IF(B7="","",IF(ROUND(AG$8-F7,3)=0,0,AG$8-F7)) | H7: =IF($G7="",0,I7+$E7) | I7: =IF($G7="","",IF(ROUND($G7,3)=0,0,IF($G7>0,VLOOKUP($G7,Boundaries!$B$5:$C$9153,2,TRUE),-1*VLOOKUP(-1*$G7,Boundaries!$B$5:$C154,2,TRUE)))) | J7: =IF(I7="","",VLOOKUP(I7,Key!$A$2:$B$982,2,FALSE)) | K7: =IF(I7="","",IF(I7=0,"",IF(I7>0,VLOOKUP(I7,Commas!$A$2:$E$9149,5,FALSE),-1*VLOOKUP(-1*I7,Commas!$A$2:$E$9149,5,FALSE)))) | L7: =IF($B7="","",IF($G7="",0,IF(K7="",$G7,ABS($G7-K7)))) | M7: =IF($G7="",0,N7+$E7) | N7: =IF($G7="","",IF(ROUND($G7,3)=0,0,IF($G7>0,VLOOKUP($G7,Boundaries!$F$5:$G$9153,2,TRUE),-1*VLOOKUP(-1*$G7,Boundaries!$F$5:$G$9153,2,TRUE)))) | O7: =IF(N7="","",VLOOKUP(N7,Key!$A$2:$B$982,2,FALSE)) | P7: =IF(N7="","",IF(N7=0,"",IF(N7>0,VLOOKUP(N7,Commas!$A$2:$E$9149,5,FALSE),-1*VLOOKUP(-1*N7,Commas!$A$2:$E$9149,5,FALSE)))) | Q7: =IF($B7="","",IF($G7="",0,IF(P7="",$G7,ABS($G7-P7)))) | R7: =IF($G7="",0,S7+$E7) | S7: =IF($G7="","",IF(ROUND($G7,3)=0,0,IF($G7>0,VLOOKUP($G7,Boundaries!$J$5:$K$9153,2,TRUE),-1*VLOOKUP(-1*$G7,Boundaries!$J$5:$K$9153,2,TRUE)))) | T7: =IF(S7="","",VLOOKUP(S7,Key!$A$2:$B$982,2,FALSE)) | U7: =IF(S7="","",IF(S7=0,"",IF(S7>0,VLOOKUP(S7,Commas!$A$2:$E$9149,5,FALSE),-1*VLOOKUP(-1*S7,Commas!$A$2:$E$9149,5,FALSE)))) | V7: =IF($B7="","",IF($G7="",0,IF(U7="",0,ABS($G7-U7)))) | W7: =IF($G7="",0,X7+$E7) | X7: =IF($G7="","",IF(ROUND($G7,3)=0,0,IF($G7>0,VLOOKUP($G7,Boundaries!$N$5:$O$9153,2,TRUE),-1*VLOOKUP(-1*$G7,Boundaries!$N$5:$O$9153,2,TRUE)))) | Y7: =IF(X7="","",VLOOKUP(X7,Key!$A$2:$B$982,2,FALSE)) | Z7: =IF(X7="","",IF(X7=0,"",IF(X7>0,VLOOKUP(X7,Commas!$A$2:$E$9149,5,FALSE),-1*VLOOKUP(-1*X7,Commas!$A$2:$E$9149,5,FALSE)))) | AA7: =IF($B7="","",IF($G7="",0,IF(Z7="",0,ABS($G7-Z7)))) | AB7: =IF(B7<>"",UI!$C$8+(FIND(D7&B7&REPT(" ",3-LEN(D7&B7)),$A$1)-46)/3-AJ$2,"") | AG7: =(3^((FIND(UI!$C$13&REPT(" ",3-LEN(UI!$C$13)),$A$1)-46)/3)) | AH7: nominal mulitplier
A8: =1200*(LN(81/64)/LN(2)) | B8: =IF(ABS(AG$8-A8)>2.000001*AD$2,"","E") | C8: =IF(ABS(AG$8-A8)>2.000001*AD$2,""," ") | D8: =IF(B8="","",IF(AG$8-A8>AD$2*(1+AD$4),"x",IF(AG$8-A8>AD$2*AD$4,"#",IF(A8-AG$8>AD$2*(1+AD$4),"bb",IF(A8-AG$8>AD$2*AD$4,"b",""))))) | E8: =IF(D8="x",2000,IF(D8="#",1000,IF(D8="",0,IF(D8="b",-1000,IF(D8="bb",-2000))))) | F8: =IF(B8="","",IF(AG$8-A8>AD$2*(1+AD$4),A8+AD$2*2,IF(AG$8-A8>AD$2*AD$4,A8+AD$2,IF(A8-AG$8>AD$2*(1+AD$4),A8-2*AD$2,IF(A8-AG$8>AD$2*AD$4,A8-AD$2,A8))))) | G8: =IF(B8="","",IF(ROUND(AG$8-F8,3)=0,0,AG$8-F8)) | H8: =IF($G8="",0,I8+$E8) | I8: =IF($G8="","",IF(ROUND($G8,3)=0,0,IF($G8>0,VLOOKUP($G8,Boundaries!$B$5:$C$9153,2,TRUE),-1*VLOOKUP(-1*$G8,Boundaries!$B$5:$C155,2,TRUE)))) | J8: =IF(I8="","",VLOOKUP(I8,Key!$A$2:$B$982,2,FALSE)) | K8: =IF(I8="","",IF(I8=0,"",IF(I8>0,VLOOKUP(I8,Commas!$A$2:$E$9149,5,FALSE),-1*VLOOKUP(-1*I8,Commas!$A$2:$E$9149,5,FALSE)))) | L8: =IF($B8="","",IF($G8="",0,IF(K8="",$G8,ABS($G8-K8)))) | M8: =IF($G8="",0,N8+$E8) | N8: =IF($G8="","",IF(ROUND($G8,3)=0,0,IF($G8>0,VLOOKUP($G8,Boundaries!$F$5:$G$9153,2,TRUE),-1*VLOOKUP(-1*$G8,Boundaries!$F$5:$G$9153,2,TRUE)))) | O8: =IF(N8="","",VLOOKUP(N8,Key!$A$2:$B$982,2,FALSE)) | P8: =IF(N8="","",IF(N8=0,"",IF(N8>0,VLOOKUP(N8,Commas!$A$2:$E$9149,5,FALSE),-1*VLOOKUP(-1*N8,Commas!$A$2:$E$9149,5,FALSE)))) | Q8: =IF($B8="","",IF($G8="",0,IF(P8="",$G8,ABS($G8-P8)))) | R8: =IF($G8="",0,S8+$E8) | S8: =IF($G8="","",IF(ROUND($G8,3)=0,0,IF($G8>0,VLOOKUP($G8,Boundaries!$J$5:$K$9153,2,TRUE),-1*VLOOKUP(-1*$G8,Boundaries!$J$5:$K$9153,2,TRUE)))) | T8: =IF(S8="","",VLOOKUP(S8,Key!$A$2:$B$982,2,FALSE)) | U8: =IF(S8="","",IF(S8=0,"",IF(S8>0,VLOOKUP(S8,Commas!$A$2:$E$9149,5,FALSE),-1*VLOOKUP(-1*S8,Commas!$A$2:$E$9149,5,FALSE)))) | V8: =IF($B8="","",IF($G8="",0,IF(U8="",0,ABS($G8-U8)))) | W8: =IF($G8="",0,X8+$E8) | X8: =IF($G8="","",IF(ROUND($G8,3)=0,0,IF($G8>0,VLOOKUP($G8,Boundaries!$N$5:$O$9153,2,TRUE),-1*VLOOKUP(-1*$G8,Boundaries!$N$5:$O$9153,2,TRUE)))) | Y8: =IF(X8="","",VLOOKUP(X8,Key!$A$2:$B$982,2,FALSE)) | Z8: =IF(X8="","",IF(X8=0,"",IF(X8>0,VLOOKUP(X8,Commas!$A$2:$E$9149,5,FALSE),-1*VLOOKUP(-1*X8,Commas!$A$2:$E$9149,5,FALSE)))) | AA8: =IF($B8="","",IF($G8="",0,IF(Z8="",0,ABS($G8-Z8)))) | AB8: =IF(B8<>"",UI!$C$8+(FIND(D8&B8&REPT(" ",3-LEN(D8&B8)),$A$1)-46)/3-AJ$2,"") | AG8: =MOD(1200*(LOG(AG4*AG7,2)),1200) | AH8: cents above C
A9: =1200*(LN(4/3)/LN(2)) | B9: =IF(ABS(AG$8-A9)>2.000001*AD$2,"","F") | C9: =IF(ABS(AG$8-A9)>2.000001*AD$2,""," ") | D9: =IF(B9="","",IF(AG$8-A9>AD$2*(1+AD$4),"x",IF(AG$8-A9>AD$2*AD$4,"#",IF(A9-AG$8>AD$2*(1+AD$4),"bb",IF(A9-AG$8>AD$2*AD$4,"b",""))))) | E9: =IF(D9="x",2000,IF(D9="#",1000,IF(D9="",0,IF(D9="b",-1000,IF(D9="bb",-2000))))) | F9: =IF(B9="","",IF(AG$8-A9>AD$2*(1+AD$4),A9+AD$2*2,IF(AG$8-A9>AD$2*AD$4,A9+AD$2,IF(A9-AG$8>AD$2*(1+AD$4),A9-2*AD$2,IF(A9-AG$8>AD$2*AD$4,A9-AD$2,A9))))) | G9: =IF(B9="","",IF(ROUND(AG$8-F9,3)=0,0,AG$8-F9)) | H9: =IF($G9="",0,I9+$E9) | I9: =IF($G9="","",IF(ROUND($G9,3)=0,0,IF($G9>0,VLOOKUP($G9,Boundaries!$B$5:$C$9153,2,TRUE),-1*VLOOKUP(-1*$G9,Boundaries!$B$5:$C156,2,TRUE)))) | J9: =IF(I9="","",VLOOKUP(I9,Key!$A$2:$B$982,2,FALSE)) | K9: =IF(I9="","",IF(I9=0,"",IF(I9>0,VLOOKUP(I9,Commas!$A$2:$E$9149,5,FALSE),-1*VLOOKUP(-1*I9,Commas!$A$2:$E$9149,5,FALSE)))) | L9: =IF($B9="","",IF($G9="",0,IF(K9="",$G9,ABS($G9-K9)))) | M9: =IF($G9="",0,N9+$E9) | N9: =IF($G9="","",IF(ROUND($G9,3)=0,0,IF($G9>0,VLOOKUP($G9,Boundaries!$F$5:$G$9153,2,TRUE),-1*VLOOKUP(-1*$G9,Boundaries!$F$5:$G$9153,2,TRUE)))) | O9: =IF(N9="","",VLOOKUP(N9,Key!$A$2:$B$982,2,FALSE)) | P9: =IF(N9="","",IF(N9=0,"",IF(N9>0,VLOOKUP(N9,Commas!$A$2:$E$9149,5,FALSE),-1*VLOOKUP(-1*N9,Commas!$A$2:$E$9149,5,FALSE)))) | Q9: =IF($B9="","",IF($G9="",0,IF(P9="",$G9,ABS($G9-P9)))) | R9: =IF($G9="",0,S9+$E9) | S9: =IF($G9="","",IF(ROUND($G9,3)=0,0,IF($G9>0,VLOOKUP($G9,Boundaries!$J$5:$K$9153,2,TRUE),-1*VLOOKUP(-1*$G9,Boundaries!$J$5:$K$9153,2,TRUE)))) | T9: =IF(S9="","",VLOOKUP(S9,Key!$A$2:$B$982,2,FALSE)) | U9: =IF(S9="","",IF(S9=0,"",IF(S9>0,VLOOKUP(S9,Commas!$A$2:$E$9149,5,FALSE),-1*VLOOKUP(-1*S9,Commas!$A$2:$E$9149,5,FALSE)))) | V9: =IF($B9="","",IF($G9="",0,IF(U9="",0,ABS($G9-U9)))) | W9: =IF($G9="",0,X9+$E9) | X9: =IF($G9="","",IF(ROUND($G9,3)=0,0,IF($G9>0,VLOOKUP($G9,Boundaries!$N$5:$O$9153,2,TRUE),-1*VLOOKUP(-1*$G9,Boundaries!$N$5:$O$9153,2,TRUE)))) | Y9: =IF(X9="","",VLOOKUP(X9,Key!$A$2:$B$982,2,FALSE)) | Z9: =IF(X9="","",IF(X9=0,"",IF(X9>0,VLOOKUP(X9,Commas!$A$2:$E$9149,5,FALSE),-1*VLOOKUP(-1*X9,Commas!$A$2:$E$9149,5,FALSE)))) | AA9: =IF($B9="","",IF($G9="",0,IF(Z9="",0,ABS($G9-Z9)))) | AB9: =IF(B9<>"",UI!$C$8+(FIND(D9&B9&REPT(" ",3-LEN(D9&B9)),$A$1)-46)/3-AJ$2,"")
A10: =1200*(LN(3/2)/LN(2)) | B10: =IF(ABS(AG$8-A10)>2.000001*AD$2,"","G") | C10: =IF(ABS(AG$8-A10)>2.000001*AD$2,""," ") | D10: =IF(B10="","",IF(AG$8-A10>AD$2*(1+AD$4),"x",IF(AG$8-A10>AD$2*AD$4,"#",IF(A10-AG$8>AD$2*(1+AD$4),"bb",IF(A10-AG$8>AD$2*AD$4,"b",""))))) | E10: =IF(D10="x",2000,IF(D10="#",1000,IF(D10="",0,IF(D10="b",-1000,IF(D10="bb",-2000))))) | F10: =IF(B10="","",IF(AG$8-A10>AD$2*(1+AD$4),A10+AD$2*2,IF(AG$8-A10>AD$2*AD$4,A10+AD$2,IF(A10-AG$8>AD$2*(1+AD$4),A10-2*AD$2,IF(A10-AG$8>AD$2*AD$4,A10-AD$2,A10))))) | G10: =IF(B10="","",IF(ROUND(AG$8-F10,3)=0,0,AG$8-F10)) | H10: =IF($G10="",0,I10+$E10) | I10: =IF($G10="","",IF(ROUND($G10,3)=0,0,IF($G10>0,VLOOKUP($G10,Boundaries!$B$5:$C$9153,2,TRUE),-1*VLOOKUP(-1*$G10,Boundaries!$B$5:$C157,2,TRUE)))) | J10: =IF(I10="","",VLOOKUP(I10,Key!$A$2:$B$982,2,FALSE)) | K10: =IF(I10="","",IF(I10=0,"",IF(I10>0,VLOOKUP(I10,Commas!$A$2:$E$9149,5,FALSE),-1*VLOOKUP(-1*I10,Commas!$A$2:$E$9149,5,FALSE)))) | L10: =IF($B10="","",IF($G10="",0,IF(K10="",$G10,ABS($G10-K10)))) | M10: =IF($G10="",0,N10+$E10) | N10: =IF($G10="","",IF(ROUND($G10,3)=0,0,IF($G10>0,VLOOKUP($G10,Boundaries!$F$5:$G$9153,2,TRUE),-1*VLOOKUP(-1*$G10,Boundaries!$F$5:$G$9153,2,TRUE)))) | O10: =IF(N10="","",VLOOKUP(N10,Key!$A$2:$B$982,2,FALSE)) | P10: =IF(N10="","",IF(N10=0,"",IF(N10>0,VLOOKUP(N10,Commas!$A$2:$E$9149,5,FALSE),-1*VLOOKUP(-1*N10,Commas!$A$2:$E$9149,5,FALSE)))) | Q10: =IF($B10="","",IF($G10="",0,IF(P10="",$G10,ABS($G10-P10)))) | R10: =IF($G10="",0,S10+$E10) | S10: =IF($G10="","",IF(ROUND($G10,3)=0,0,IF($G10>0,VLOOKUP($G10,Boundaries!$J$5:$K$9153,2,TRUE),-1*VLOOKUP(-1*$G10,Boundaries!$J$5:$K$9153,2,TRUE)))) | T10: =IF(S10="","",VLOOKUP(S10,Key!$A$2:$B$982,2,FALSE)) | U10: =IF(S10="","",IF(S10=0,"",IF(S10>0,VLOOKUP(S10,Commas!$A$2:$E$9149,5,FALSE),-1*VLOOKUP(-1*S10,Commas!$A$2:$E$9149,5,FALSE)))) | V10: =IF($B10="","",IF($G10="",0,IF(U10="",0,ABS($G10-U10)))) | W10: =IF($G10="",0,X10+$E10) | X10: =IF($G10="","",IF(ROUND($G10,3)=0,0,IF($G10>0,VLOOKUP($G10,Boundaries!$N$5:$O$9153,2,TRUE),-1*VLOOKUP(-1*$G10,Boundaries!$N$5:$O$9153,2,TRUE)))) | Y10: =IF(X10="","",VLOOKUP(X10,Key!$A$2:$B$982,2,FALSE)) | Z10: =IF(X10="","",IF(X10=0,"",IF(X10>0,VLOOKUP(X10,Commas!$A$2:$E$9149,5,FALSE),-1*VLOOKUP(-1*X10,Commas!$A$2:$E$9149,5,FALSE)))) | AA10: =IF($B10="","",IF($G10="",0,IF(Z10="",0,ABS($G10-Z10)))) | AB10: =IF(B10<>"",UI!$C$8+(FIND(D10&B10&REPT(" ",3-LEN(D10&B10)),$A$1)-46)/3-AJ$2,"")
A11: =1200*(LN(27/16)/LN(2)) | B11: =IF(ABS(AG$8-A11)>2.000001*AD$2,"","A") | C11: =IF(ABS(AG$8-A11)>2.000001*AD$2,""," ") | D11: =IF(B11="","",IF(AG$8-A11>AD$2*(1+AD$4),"x",IF(AG$8-A11>AD$2*AD$4,"#",IF(A11-AG$8>AD$2*(1+AD$4),"bb",IF(A11-AG$8>AD$2*AD$4,"b",""))))) | E11: =IF(D11="x",2000,IF(D11="#",1000,IF(D11="",0,IF(D11="b",-1000,IF(D11="bb",-2000))))) | F11: =IF(B11="","",IF(AG$8-A11>AD$2*(1+AD$4),A11+AD$2*2,IF(AG$8-A11>AD$2*AD$4,A11+AD$2,IF(A11-AG$8>AD$2*(1+AD$4),A11-2*AD$2,IF(A11-AG$8>AD$2*AD$4,A11-AD$2,A11))))) | G11: =IF(B11="","",IF(ROUND(AG$8-F11,3)=0,0,AG$8-F11)) | H11: =IF($G11="",0,I11+$E11) | I11: =IF($G11="","",IF(ROUND($G11,3)=0,0,IF($G11>0,VLOOKUP($G11,Boundaries!$B$5:$C$9153,2,TRUE),-1*VLOOKUP(-1*$G11,Boundaries!$B$5:$C158,2,TRUE)))) | J11: =IF(I11="","",VLOOKUP(I11,Key!$A$2:$B$982,2,FALSE)) | K11: =IF(I11="","",IF(I11=0,"",IF(I11>0,VLOOKUP(I11,Commas!$A$2:$E$9149,5,FALSE),-1*VLOOKUP(-1*I11,Commas!$A$2:$E$9149,5,FALSE)))) | L11: =IF($B11="","",IF($G11="",0,IF(K11="",$G11,ABS($G11-K11)))) | M11: =IF($G11="",0,N11+$E11) | N11: =IF($G11="","",IF(ROUND($G11,3)=0,0,IF($G11>0,VLOOKUP($G11,Boundaries!$F$5:$G$9153,2,TRUE),-1*VLOOKUP(-1*$G11,Boundaries!$F$5:$G$9153,2,TRUE)))) | O11: =IF(N11="","",VLOOKUP(N11,Key!$A$2:$B$982,2,FALSE)) | P11: =IF(N11="","",IF(N11=0,"",IF(N11>0,VLOOKUP(N11,Commas!$A$2:$E$9149,5,FALSE),-1*VLOOKUP(-1*N11,Commas!$A$2:$E$9149,5,FALSE)))) | Q11: =IF($B11="","",IF($G11="",0,IF(P11="",$G11,ABS($G11-P11)))) | R11: =IF($G11="",0,S11+$E11) | S11: =IF($G11="","",IF(ROUND($G11,3)=0,0,IF($G11>0,VLOOKUP($G11,Boundaries!$J$5:$K$9153,2,TRUE),-1*VLOOKUP(-1*$G11,Boundaries!$J$5:$K$9153,2,TRUE)))) | T11: =IF(S11="","",VLOOKUP(S11,Key!$A$2:$B$982,2,FALSE)) | U11: =IF(S11="","",IF(S11=0,"",IF(S11>0,VLOOKUP(S11,Commas!$A$2:$E$9149,5,FALSE),-1*VLOOKUP(-1*S11,Commas!$A$2:$E$9149,5,FALSE)))) | V11: =IF($B11="","",IF($G11="",0,IF(U11="",0,ABS($G11-U11)))) | W11: =IF($G11="",0,X11+$E11) | X11: =IF($G11="","",IF(ROUND($G11,3)=0,0,IF($G11>0,VLOOKUP($G11,Boundaries!$N$5:$O$9153,2,TRUE),-1*VLOOKUP(-1*$G11,Boundaries!$N$5:$O$9153,2,TRUE)))) | Y11: =IF(X11="","",VLOOKUP(X11,Key!$A$2:$B$982,2,FALSE)) | Z11: =IF(X11="","",IF(X11=0,"",IF(X11>0,VLOOKUP(X11,Commas!$A$2:$E$9149,5,FALSE),-1*VLOOKUP(-1*X11,Commas!$A$2:$E$9149,5,FALSE)))) | AA11: =IF($B11="","",IF($G11="",0,IF(Z11="",0,ABS($G11-Z11)))) | AB11: =IF(B11<>"",UI!$C$8+(FIND(D11&B11&REPT(" ",3-LEN(D11&B11)),$A$1)-46)/3-AJ$2,"")
A12: =IF(ABS(AG$8-1200*(LN(243/128)/LN(2))+1200)<300,1200*(LN(243/128)/LN(2))-1200,1200*(LN(243/128)/LN(2))) | B12: =IF(ABS(AG$8-A12)>2.000001*AD$2,"","B") | C12: =IF(ABS(AG$8-A12)>2.000001*AD$2,""," ") | D12: =IF(B12="","",IF(AG$8-A12>AD$2*(1+AD$4),"x",IF(AG$8-A12>AD$2*AD$4,"#",IF(A12-AG$8>AD$2*(1+AD$4),"bb",IF(A12-AG$8>AD$2*AD$4,"b",""))))) | E12: =IF(D12="x",2000,IF(D12="#",1000,IF(D12="",0,IF(D12="b",-1000,IF(D12="bb",-2000))))) | F12: =IF(B12="","",IF(AG$8-A12>AD$2*(1+AD$4),A12+AD$2*2,IF(AG$8-A12>AD$2*AD$4,A12+AD$2,IF(A12-AG$8>AD$2*(1+AD$4),A12-2*AD$2,IF(A12-AG$8>AD$2*AD$4,A12-AD$2,A12))))) | G12: =IF(B12="","",IF(ROUND(AG$8-F12,3)=0,0,AG$8-F12)) | H12: =IF($G12="",0,I12+$E12) | I12: =IF($G12="","",IF(ROUND($G12,3)=0,0,IF($G12>0,VLOOKUP($G12,Boundaries!$B$5:$C$9153,2,TRUE),-1*VLOOKUP(-1*$G12,Boundaries!$B$5:$C159,2,TRUE)))) | J12: =IF(I12="","",VLOOKUP(I12,Key!$A$2:$B$982,2,FALSE)) | K12: =IF(I12="","",IF(I12=0,"",IF(I12>0,VLOOKUP(I12,Commas!$A$2:$E$9149,5,FALSE),-1*VLOOKUP(-1*I12,Commas!$A$2:$E$9149,5,FALSE)))) | L12: =IF($B12="","",IF($G12="",0,IF(K12="",$G12,ABS($G12-K12)))) | M12: =IF($G12="",0,N12+$E12) | N12: =IF($G12="","",IF(ROUND($G12,3)=0,0,IF($G12>0,VLOOKUP($G12,Boundaries!$F$5:$G$9153,2,TRUE),-1*VLOOKUP(-1*$G12,Boundaries!$F$5:$G$9153,2,TRUE)))) | O12: =IF(N12="","",VLOOKUP(N12,Key!$A$2:$B$982,2,FALSE)) | P12: =IF(N12="","",IF(N12=0,"",IF(N12>0,VLOOKUP(N12,Commas!$A$2:$E$9149,5,FALSE),-1*VLOOKUP(-1*N12,Commas!$A$2:$E$9149,5,FALSE)))) | Q12: =IF($B12="","",IF($G12="",0,IF(P12="",$G12,ABS($G12-P12)))) | R12: =IF($G12="",0,S12+$E12) | S12: =IF($G12="","",IF(ROUND($G12,3)=0,0,IF($G12>0,VLOOKUP($G12,Boundaries!$J$5:$K$9153,2,TRUE),-1*VLOOKUP(-1*$G12,Boundaries!$J$5:$K$9153,2,TRUE)))) | T12: =IF(S12="","",VLOOKUP(S12,Key!$A$2:$B$982,2,FALSE)) | U12: =IF(S12="","",IF(S12=0,"",IF(S12>0,VLOOKUP(S12,Commas!$A$2:$E$9149,5,FALSE),-1*VLOOKUP(-1*S12,Commas!$A$2:$E$9149,5,FALSE)))) | V12: =IF($B12="","",IF($G12="",0,IF(U12="",0,ABS($G12-U12)))) | W12: =IF($G12="",0,X12+$E12) | X12: =IF($G12="","",IF(ROUND($G12,3)=0,0,IF($G12>0,VLOOKUP($G12,Boundaries!$N$5:$O$9153,2,TRUE),-1*VLOOKUP(-1*$G12,Boundaries!$N$5:$O$9153,2,TRUE)))) | Y12: =IF(X12="","",VLOOKUP(X12,Key!$A$2:$B$982,2,FALSE)) | Z12: =IF(X12="","",IF(X12=0,"",IF(X12>0,VLOOKUP(X12,Commas!$A$2:$E$9149,5,FALSE),-1*VLOOKUP(-1*X12,Commas!$A$2:$E$9149,5,FALSE)))) | AA12: =IF($B12="","",IF($G12="",0,IF(Z12="",0,ABS($G12-Z12)))) | AB12: =IF(B12<>"",UI!$C$8+(FIND(D12&B12&REPT(" ",3-LEN(D12&B12)),$A$1)-46)/3-AJ$2,"")
I13: =IF($G13="","",IF(ROUND($G13,3)=0,0,IF($G13>0,VLOOKUP($G13,Boundaries!$B$5:$C$9153,2,TRUE),-1*VLOOKUP(-1*$G13,Boundaries!$B$5:$C160,2,TRUE)))) | N13: =IF($G13="","",IF(ROUND($G13,3)=0,0,IF($G13>0,VLOOKUP($G13,Boundaries!$F$5:$G$9153,2,TRUE),-1*VLOOKUP(-1*$G13,Boundaries!$F$5:$G$9153,2,TRUE)))) | S13: =IF($G13="","",IF(ROUND($G13,3)=0,0,IF($G13>0,VLOOKUP($G13,Boundaries!$J$5:$K$9153,2,TRUE),-1*VLOOKUP(-1*$G13,Boundaries!$J$5:$K$9153,2,TRUE)))) | X13: =IF($G13="","",IF(ROUND($G13,3)=0,0,IF($G13>0,VLOOKUP($G13,Boundaries!$N$5:$O$9153,2,TRUE),-1*VLOOKUP(-1*$G13,Boundaries!$N$5:$O$9153,2,TRUE))))

Sheet Boundaries
A1: Standard Medium Precision JI | E1: Standard High Precision JI | I1: Standard Ultra Precision JI | M1: Standard Extreme Precision JI
A2: steps per apotome | D2: 21 | E2: steps per apotome | H2: 47 | I2: steps per apotome | L2: 58 | M2: steps per apotome | P2: 233
A3: cents per step (approx.) | D3: =LN(3^7/2^11)/LN(2)*1200/D$2 | E3: cents per step (approx.) | H3: =LN(3^7/2^11)/LN(2)*1200/H$2 | I3: cents per step (approx.) | L3: =LN(3^7/2^11)/LN(2)*1200/L$2 | M3: cents per step (approx.) | P3: =LN(3^7/2^11)/LN(2)*1200/P$2
A4: Steps | B4: Lower Bound | C4: Key | D4: Symbol | E4: Steps | F4: Lower Bound | G4: Key | H4: Symbol | I4: Steps | J4: Lower Bound | K4: Key | L4: Symbol | M4: Steps | N4: Lower Bound | O4: Key | P4: Symbol
A5: 0 | B5: -0.21078802 | C5: 0 | D5: =IF(ISERROR(VLOOKUP(C5,Key!$A$2:$B$982,2,FALSE)),"",VLOOKUP(C5,Key!$A$2:$B$982,2,FALSE)) | E5: 0 | F5: -0.21078802 | G5: 0 | H5: =IF(ISERROR(VLOOKUP(G5,Key!$A$2:$B$982,2,FALSE)),"",VLOOKUP(G5,Key!$A$2:$B$982,2,FALSE)) | I5: 0 | J5: -0.21078802 | K5: 0 | L5: =IF(ISERROR(VLOOKUP(K5,Key!$A$2:$B$982,2,FALSE)),"",VLOOKUP(K5,Key!$A$2:$B$982,2,FALSE)) | M5: 0 | N5: =(ROUND((M5-0.5)/233*809+0.5,0)-0.5)/809*Calculator!$AD$2 | O5: 0 | P5: =IF(ISERROR(VLOOKUP(O5,Key!$A$2:$B$982,2,FALSE)),"",VLOOKUP(O5,Key!$A$2:$B$982,2,FALSE))
D6: =IF(ISERROR(VLOOKUP(C6,Key!$A$2:$B$982,2,FALSE)),"",VLOOKUP(C6,Key!$A$2:$B$982,2,FALSE)) | H6: =IF(ISERROR(VLOOKUP(G6,Key!$A$2:$B$982,2,FALSE)),"",VLOOKUP(G6,Key!$A$2:$B$982,2,FALSE)) | L6: =IF(ISERROR(VLOOKUP(K6,Key!$A$2:$B$982,2,FALSE)),"",VLOOKUP(K6,Key!$A$2:$B$982,2,FALSE)) | M6: 1 | N6: =(ROUND((M6-0.5)/233*809+0.5,0)-0.5)/809*Calculator!$AD$2 | O6: 1 | P6: =IF(ISERROR(VLOOKUP(O6,Key!$A$2:$B$982,2,FALSE)),"",VLOOKUP(O6,Key!$A$2:$B$982,2,FALSE))
D7: =IF(ISERROR(VLOOKUP(C7,Key!$A$2:$B$982,2,FALSE)),"",VLOOKUP(C7,Key!$A$2:$B$982,2,FALSE)) | H7: =IF(ISERROR(VLOOKUP(G7,Key!$A$2:$B$982,2,FALSE)),"",VLOOKUP(G7,Key!$A$2:$B$982,2,FALSE)) | L7: =IF(ISERROR(VLOOKUP(K7,Key!$A$2:$B$982,2,FALSE)),"",VLOOKUP(K7,Key!$A$2:$B$982,2,FALSE)) | M7: 2 | N7: =(ROUND((M7-0.5)/233*809+0.5,0)-0.5)/809*Calculator!$AD$2 | O7: 2 | P7: =IF(ISERROR(VLOOKUP(O7,Key!$A$2:$B$982,2,FALSE)),"",VLOOKUP(O7,Key!$A$2:$B$982,2,FALSE))
D8: =IF(ISERROR(VLOOKUP(C8,Key!$A$2:$B$982,2,FALSE)),"",VLOOKUP(C8,Key!$A$2:$B$982,2,FALSE)) | E8: 1 | F8: 1.1944655 | G8: 7 | H8: =IF(ISERROR(VLOOKUP(G8,Key!$A$2:$B$982,2,FALSE)),"",VLOOKUP(G8,Key!$A$2:$B$982,2,FALSE)) | I8: 1 | J8: 1.1944655 | K8: 3 | L8: =IF(ISERROR(VLOOKUP(K8,Key!$A$2:$B$982,2,FALSE)),"",VLOOKUP(K8,Key!$A$2:$B$982,2,FALSE)) | M8: 3 | N8: =(ROUND((M8-0.5)/233*809+0.5,0)-0.5)/809*Calculator!$AD$2 | O8: 3 | P8: =IF(ISERROR(VLOOKUP(O8,Key!$A$2:$B$982,2,FALSE)),"",VLOOKUP(O8,Key!$A$2:$B$982,2,FALSE))
D9: =IF(ISERROR(VLOOKUP(C9,Key!$A$2:$B$982,2,FALSE)),"",VLOOKUP(C9,Key!$A$2:$B$982,2,FALSE)) | H9: =IF(ISERROR(VLOOKUP(G9,Key!$A$2:$B$982,2,FALSE)),"",VLOOKUP(G9,Key!$A$2:$B$982,2,FALSE)) | I9: 1.3 | J9: 1.7565668 | K9: 4 | L9: =IF(ISERROR(VLOOKUP(K9,Key!$A$2:$B$982,2,FALSE)),"",VLOOKUP(K9,Key!$A$2:$B$982,2,FALSE)) | M9: 4 | N9: =(ROUND((M9-0.5)/233*809+0.5,0)-0.5)/809*Calculator!$AD$2 | O9: 4 | P9: =IF(ISERROR(VLOOKUP(O9,Key!$A$2:$B$982,2,FALSE)),"",VLOOKUP(O9,Key!$A$2:$B$982,2,FALSE))
D10: =IF(ISERROR(VLOOKUP(C10,Key!$A$2:$B$982,2,FALSE)),"",VLOOKUP(C10,Key!$A$2:$B$982,2,FALSE)) | H10: =IF(ISERROR(VLOOKUP(G10,Key!$A$2:$B$982,2,FALSE)),"",VLOOKUP(G10,Key!$A$2:$B$982,2,FALSE)) | L10: =IF(ISERROR(VLOOKUP(K10,Key!$A$2:$B$982,2,FALSE)),"",VLOOKUP(K10,Key!$A$2:$B$982,2,FALSE)) | M10: 5 | N10: =(ROUND((M10-0.5)/233*809+0.5,0)-0.5)/809*Calculator!$AD$2 | O10: 5 | P10: =IF(ISERROR(VLOOKUP(O10,Key!$A$2:$B$982,2,FALSE)),"",VLOOKUP(O10,Key!$A$2:$B$982,2,FALSE))
A11: 1 | B11: 2.7402443 | C11: 12 | D11: =IF(ISERROR(VLOOKUP(C11,Key!$A$2:$B$982,2,FALSE)),"",VLOOKUP(C11,Key!$A$2:$B$982,2,FALSE)) | H11: =IF(ISERROR(VLOOKUP(G11,Key!$A$2:$B$982,2,FALSE)),"",VLOOKUP(G11,Key!$A$2:$B$982,2,FALSE)) | I11: 2 | J11: 2.7402443 | K11: 7 | L11: =IF(ISERROR(VLOOKUP(K11,Key!$A$2:$B$982,2,FALSE)),"",VLOOKUP(K11,Key!$A$2:$B$982,2,FALSE)) | M11: 6 | N11: =(ROUND((M11-0.5)/233*809+0.5,0)-0.5)/809*Calculator!$AD$2 | O11: 6 | P11: =IF(ISERROR(VLOOKUP(O11,Key!$A$2:$B$982,2,FALSE)),"",VLOOKUP(O11,Key!$A$2:$B$982,2,FALSE))
D12: =IF(ISERROR(VLOOKUP(C12,Key!$A$2:$B$982,2,FALSE)),"",VLOOKUP(C12,Key!$A$2:$B$982,2,FALSE)) | H12: =IF(ISERROR(VLOOKUP(G12,Key!$A$2:$B$982,2,FALSE)),"",VLOOKUP(G12,Key!$A$2:$B$982,2,FALSE)) | L12: =IF(ISERROR(VLOOKUP(K12,Key!$A$2:$B$982,2,FALSE)),"",VLOOKUP(K12,Key!$A$2:$B$982,2,FALSE)) | M12: 7 | N12: =(ROUND((M12-0.5)/233*809+0.5,0)-0.5)/809*Calculator!$AD$2 | O12: 7 | P12: =IF(ISERROR(VLOOKUP(O12,Key!$A$2:$B$982,2,FALSE)),"",VLOOKUP(O12,Key!$A$2:$B$982,2,FALSE))
D13: =IF(ISERROR(VLOOKUP(C13,Key!$A$2:$B$982,2,FALSE)),"",VLOOKUP(C13,Key!$A$2:$B$982,2,FALSE)) | H13: =IF(ISERROR(VLOOKUP(G13,Key!$A$2:$B$982,2,FALSE)),"",VLOOKUP(G13,Key!$A$2:$B$982,2,FALSE)) | L13: =IF(ISERROR(VLOOKUP(K13,Key!$A$2:$B$982,2,FALSE)),"",VLOOKUP(K13,Key!$A$2:$B$982,2,FALSE)) | M13: 8 | N13: =(ROUND((M13-0.5)/233*809+0.5,0)-0.5)/809*Calculator!$AD$2 | O13: 8 | P13: =IF(ISERROR(VLOOKUP(O13,Key!$A$2:$B$982,2,FALSE)),"",VLOOKUP(O13,Key!$A$2:$B$982,2,FALSE))
D14: =IF(ISERROR(VLOOKUP(C14,Key!$A$2:$B$982,2,FALSE)),"",VLOOKUP(C14,Key!$A$2:$B$982,2,FALSE)) | H14: =IF(ISERROR(VLOOKUP(G14,Key!$A$2:$B$982,2,FALSE)),"",VLOOKUP(G14,Key!$A$2:$B$982,2,FALSE)) | L14: =IF(ISERROR(VLOOKUP(K14,Key!$A$2:$B$982,2,FALSE)),"",VLOOKUP(K14,Key!$A$2:$B$982,2,FALSE)) | M14: 9 | N14: =(ROUND((M14-0.5)/233*809+0.5,0)-0.5)/809*Calculator!$AD$2 | O14: 9 | P14: =IF(ISERROR(VLOOKUP(O14,Key!$A$2:$B$982,2,FALSE)),"",VLOOKUP(O14,Key!$A$2:$B$982,2,FALSE))
D15: =IF(ISERROR(VLOOKUP(C15,Key!$A$2:$B$982,2,FALSE)),"",VLOOKUP(C15,Key!$A$2:$B$982,2,FALSE)) | E15: 2 | F15: 4.5670738 | G15: 12 | H15: =IF(ISERROR(VLOOKUP(G15,Key!$A$2:$B$982,2,FALSE)),"",VLOOKUP(G15,Key!$A$2:$B$982,2,FALSE)) | I15: 3 | J15: 4.5670738 | K15: 12 | L15: =IF(ISERROR(VLOOKUP(K15,Key!$A$2:$B$982,2,FALSE)),"",VLOOKUP(K15,Key!$A$2:$B$982,2,FALSE)) | M15: 10 | N15: =(ROUND((M15-0.5)/233*809+0.5,0)-0.5)/809*Calculator!$AD$2 | O15: 10 | P15: =IF(ISERROR(VLOOKUP(O15,Key!$A$2:$B$982,2,FALSE)),"",VLOOKUP(O15,Key!$A$2:$B$982,2,FALSE))
D16: =IF(ISERROR(VLOOKUP(C16,Key!$A$2:$B$982,2,FALSE)),"",VLOOKUP(C16,Key!$A$2:$B$982,2,FALSE)) | H16: =IF(ISERROR(VLOOKUP(G16,Key!$A$2:$B$982,2,FALSE)),"",VLOOKUP(G16,Key!$A$2:$B$982,2,FALSE)) | L16: =IF(ISERROR(VLOOKUP(K16,Key!$A$2:$B$982,2,FALSE)),"",VLOOKUP(K16,Key!$A$2:$B$982,2,FALSE)) | M16: 11 | N16: =(ROUND((M16-0.5)/233*809+0.5,0)-0.5)/809*Calculator!$AD$2 | O16: 11 | P16: =IF(ISERROR(VLOOKUP(O16,Key!$A$2:$B$982,2,FALSE)),"",VLOOKUP(O16,Key!$A$2:$B$982,2,FALSE))
D17: =IF(ISERROR(VLOOKUP(C17,Key!$A$2:$B$982,2,FALSE)),"",VLOOKUP(C17,Key!$A$2:$B$982,2,FALSE)) | H17: =IF(ISERROR(VLOOKUP(G17,Key!$A$2:$B$982,2,FALSE)),"",VLOOKUP(G17,Key!$A$2:$B$982,2,FALSE)) | L17: =IF(ISERROR(VLOOKUP(K17,Key!$A$2:$B$982,2,FALSE)),"",VLOOKUP(K17,Key!$A$2:$B$982,2,FALSE)) | M17: 12 | N17: =(ROUND((M17-0.5)/233*809+0.5,0)-0.5)/809*Calculator!$AD$2 | O17: 12 | P17: =IF(ISERROR(VLOOKUP(O17,Key!$A$2:$B$982,2,FALSE)),"",VLOOKUP(O17,Key!$A$2:$B$982,2,FALSE))
D18: =IF(ISERROR(VLOOKUP(C18,Key!$A$2:$B$982,2,FALSE)),"",VLOOKUP(C18,Key!$A$2:$B$982,2,FALSE)) | H18: =IF(ISERROR(VLOOKUP(G18,Key!$A$2:$B$982,2,FALSE)),"",VLOOKUP(G18,Key!$A$2:$B$982,2,FALSE)) | L18: =IF(ISERROR(VLOOKUP(K18,Key!$A$2:$B$982,2,FALSE)),"",VLOOKUP(K18,Key!$A$2:$B$982,2,FALSE)) | M18: 13 | N18: =(ROUND((M18-0.5)/233*809+0.5,0)-0.5)/809*Calculator!$AD$2 | O18: 13 | P18: =IF(ISERROR(VLOOKUP(O18,Key!$A$2:$B$982,2,FALSE)),"",VLOOKUP(O18,Key!$A$2:$B$982,2,FALSE))
D19: =IF(ISERROR(VLOOKUP(C19,Key!$A$2:$B$982,2,FALSE)),"",VLOOKUP(C19,Key!$A$2:$B$982,2,FALSE)) | E19: 3 | F19: 6.5344287 | G19: 18 | H19: =IF(ISERROR(VLOOKUP(G19,Key!$A$2:$B$982,2,FALSE)),"",VLOOKUP(G19,Key!$A$2:$B$982,2,FALSE)) | I19: 4 | J19: 6.5344287 | K19: 14 | L19: =IF(ISERROR(VLOOKUP(K19,Key!$A$2:$B$982,2,FALSE)),"",VLOOKUP(K19,Key!$A$2:$B$982,2,FALSE)) | M19: 14 | N19: =(ROUND((M19-0.5)/233*809+0.5,0)-0.5)/809*Calculator!$AD$2 | O19: 14 | P19: =IF(ISERROR(VLOOKUP(O19,Key!$A$2:$B$982,2,FALSE)),"",VLOOKUP(O19,Key!$A$2:$B$982,2,FALSE))
D20: =IF(ISERROR(VLOOKUP(C20,Key!$A$2:$B$982,2,FALSE)),"",VLOOKUP(C20,Key!$A$2:$B$982,2,FALSE)) | H20: =IF(ISERROR(VLOOKUP(G20,Key!$A$2:$B$982,2,FALSE)),"",VLOOKUP(G20,Key!$A$2:$B$982,2,FALSE)) | I20: 4.2 | J20: 7.09653 | K20: 16 | L20: =IF(ISERROR(VLOOKUP(K20,Key!$A$2:$B$982,2,FALSE)),"",VLOOKUP(K20,Key!$A$2:$B$982,2,FALSE)) | M20: 15 | N20: =(ROUND((M20-0.5)/233*809+0.5,0)-0.5)/809*Calculator!$AD$2 | O20: 15 | P20: =IF(ISERROR(VLOOKUP(O20,Key!$A$2:$B$982,2,FALSE)),"",VLOOKUP(O20,Key!$A$2:$B$982,2,FALSE))
D21: =IF(ISERROR(VLOOKUP(C21,Key!$A$2:$B$982,2,FALSE)),"",VLOOKUP(C21,Key!$A$2:$B$982,2,FALSE)) | H21: =IF(ISERROR(VLOOKUP(G21,Key!$A$2:$B$982,2,FALSE)),"",VLOOKUP(G21,Key!$A$2:$B$982,2,FALSE)) | L21: =IF(ISERROR(VLOOKUP(K21,Key!$A$2:$B$982,2,FALSE)),"",VLOOKUP(K21,Key!$A$2:$B$982,2,FALSE)) | M21: 16 | N21: =(ROUND((M21-0.5)/233*809+0.5,0)-0.5)/809*Calculator!$AD$2 | O21: 16 | P21: =IF(ISERROR(VLOOKUP(O21,Key!$A$2:$B$982,2,FALSE)),"",VLOOKUP(O21,Key!$A$2:$B$982,2,FALSE))
A22: 2 | B22: 8.0802075 | C22: 20 | D22: =IF(ISERROR(VLOOKUP(C22,Key!$A$2:$B$982,2,FALSE)),"",VLOOKUP(C22,Key!$A$2:$B$982,2,FALSE)) | H22: =IF(ISERROR(VLOOKUP(G22,Key!$A$2:$B$982,2,FALSE)),"",VLOOKUP(G22,Key!$A$2:$B$982,2,FALSE)) | I22: 4.6 | J22: 8.0802075 | K22: 18 | L22: =IF(ISERROR(VLOOKUP(K22,Key!$A$2:$B$982,2,FALSE)),"",VLOOKUP(K22,Key!$A$2:$B$982,2,FALSE)) | M22: 17 | N22: =(ROUND((M22-0.5)/233*809+0.5,0)-0.5)/809*Calculator!$AD$2 | O22: 17 | P22: =IF(ISERROR(VLOOKUP(O22,Key!$A$2:$B$982,2,FALSE)),"",VLOOKUP(O22,Key!$A$2:$B$982,2,FALSE))
D23: =IF(ISERROR(VLOOKUP(C23,Key!$A$2:$B$982,2,FALSE)),"",VLOOKUP(C23,Key!$A$2:$B$982,2,FALSE)) | H23: =IF(ISERROR(VLOOKUP(G23,Key!$A$2:$B$982,2,FALSE)),"",VLOOKUP(G23,Key!$A$2:$B$982,2,FALSE)) | L23: =IF(ISERROR(VLOOKUP(K23,Key!$A$2:$B$982,2,FALSE)),"",VLOOKUP(K23,Key!$A$2:$B$982,2,FALSE)) | M23: 18 | N23: =(ROUND((M23-0.5)/233*809+0.5,0)-0.5)/809*Calculator!$AD$2 | O23: 18 | P23: =IF(ISERROR(VLOOKUP(O23,Key!$A$2:$B$982,2,FALSE)),"",VLOOKUP(O23,Key!$A$2:$B$982,2,FALSE))
D24: =IF(ISERROR(VLOOKUP(C24,Key!$A$2:$B$982,2,FALSE)),"",VLOOKUP(C24,Key!$A$2:$B$982,2,FALSE)) | E24: 4 | F24: 9.0638849 | G24: 20 | H24: =IF(ISERROR(VLOOKUP(G24,Key!$A$2:$B$982,2,FALSE)),"",VLOOKUP(G24,Key!$A$2:$B$982,2,FALSE)) | I24: 5 | J24: 9.0638849 | K24: 20 | L24: =IF(ISERROR(VLOOKUP(K24,Key!$A$2:$B$982,2,FALSE)),"",VLOOKUP(K24,Key!$A$2:$B$982,2,FALSE)) | M24: 19 | N24: =(ROUND((M24-0.5)/233*809+0.5,0)-0.5)/809*Calculator!$AD$2 | O24: 19 | P24: =IF(ISERROR(VLOOKUP(O24,Key!$A$2:$B$982,2,FALSE)),"",VLOOKUP(O24,Key!$A$2:$B$982,2,FALSE))
D25: =IF(ISERROR(VLOOKUP(C25,Key!$A$2:$B$982,2,FALSE)),"",VLOOKUP(C25,Key!$A$2:$B$982,2,FALSE)) | H25: =IF(ISERROR(VLOOKUP(G25,Key!$A$2:$B$982,2,FALSE)),"",VLOOKUP(G25,Key!$A$2:$B$982,2,FALSE)) | L25: =IF(ISERROR(VLOOKUP(K25,Key!$A$2:$B$982,2,FALSE)),"",VLOOKUP(K25,Key!$A$2:$B$982,2,FALSE)) | M25: 20 | N25: =(ROUND((M25-0.5)/233*809+0.5,0)-0.5)/809*Calculator!$AD$2 | O25: 20 | P25: =IF(ISERROR(VLOOKUP(O25,Key!$A$2:$B$982,2,FALSE)),"",VLOOKUP(O25,Key!$A$2:$B$982,2,FALSE))
D26: =IF(ISERROR(VLOOKUP(C26,Key!$A$2:$B$982,2,FALSE)),"",VLOOKUP(C26,Key!$A$2:$B$982,2,FALSE)) | H26: =IF(ISERROR(VLOOKUP(G26,Key!$A$2:$B$982,2,FALSE)),"",VLOOKUP(G26,Key!$A$2:$B$982,2,FALSE)) | L26: =IF(ISERROR(VLOOKUP(K26,Key!$A$2:$B$982,2,FALSE)),"",VLOOKUP(K26,Key!$A$2:$B$982,2,FALSE)) | M26: 21 | N26: =(ROUND((M26-0.5)/233*809+0.5,0)-0.5)/809*Calculator!$AD$2 | O26: 21 | P26: =IF(ISERROR(VLOOKUP(O26,Key!$A$2:$B$982,2,FALSE)),"",VLOOKUP(O26,Key!$A$2:$B$982,2,FALSE))
D27: =IF(ISERROR(VLOOKUP(C27,Key!$A$2:$B$982,2,FALSE)),"",VLOOKUP(C27,Key!$A$2:$B$982,2,FALSE)) | H27: =IF(ISERROR(VLOOKUP(G27,Key!$A$2:$B$982,2,FALSE)),"",VLOOKUP(G27,Key!$A$2:$B$982,2,FALSE)) | L27: =IF(ISERROR(VLOOKUP(K27,Key!$A$2:$B$982,2,FALSE)),"",VLOOKUP(K27,Key!$A$2:$B$982,2,FALSE)) | M27: 22 | N27: =(ROUND((M27-0.5)/233*809+0.5,0)-0.5)/809*Calculator!$AD$2 | O27: 22 | P27: =IF(ISERROR(VLOOKUP(O27,Key!$A$2:$B$982,2,FALSE)),"",VLOOKUP(O27,Key!$A$2:$B$982,2,FALSE))
D28: =IF(ISERROR(VLOOKUP(C28,Key!$A$2:$B$982,2,FALSE)),"",VLOOKUP(C28,Key!$A$2:$B$982,2,FALSE)) | E28: 5 | F28: 11.03124 | G28: 25 | H28: =IF(ISERROR(VLOOKUP(G28,Key!$A$2:$B$982,2,FALSE)),"",VLOOKUP(G28,Key!$A$2:$B$982,2,FALSE)) | I28: 6 | J28: 11.03124 | K28: 24 | L28: =IF(ISERROR(VLOOKUP(K28,Key!$A$2:$B$982,2,FALSE)),"",VLOOKUP(K28,Key!$A$2:$B$982,2,FALSE)) | M28: 23 | N28: =(ROUND((M28-0.5)/233*809+0.5,0)-0.5)/809*Calculator!$AD$2 | O28: 23 | P28: =IF(ISERROR(VLOOKUP(O28,Key!$A$2:$B$982,2,FALSE)),"",VLOOKUP(O28,Key!$A$2:$B$982,2,FALSE))
D29: =IF(ISERROR(VLOOKUP(C29,Key!$A$2:$B$982,2,FALSE)),"",VLOOKUP(C29,Key!$A$2:$B$982,2,FALSE)) | H29: =IF(ISERROR(VLOOKUP(G29,Key!$A$2:$B$982,2,FALSE)),"",VLOOKUP(G29,Key!$A$2:$B$982,2,FALSE)) | L29: =IF(ISERROR(VLOOKUP(K29,Key!$A$2:$B$982,2,FALSE)),"",VLOOKUP(K29,Key!$A$2:$B$982,2,FALSE)) | M29: 24 | N29: =(ROUND((M29-0.5)/233*809+0.5,0)-0.5)/809*Calculator!$AD$2 | O29: 24 | P29: =IF(ISERROR(VLOOKUP(O29,Key!$A$2:$B$982,2,FALSE)),"",VLOOKUP(O29,Key!$A$2:$B$982,2,FALSE))
D30: =IF(ISERROR(VLOOKUP(C30,Key!$A$2:$B$982,2,FALSE)),"",VLOOKUP(C30,Key!$A$2:$B$982,2,FALSE)) | H30: =IF(ISERROR(VLOOKUP(G30,Key!$A$2:$B$982,2,FALSE)),"",VLOOKUP(G30,Key!$A$2:$B$982,2,FALSE)) | I30: 6.4 | J30: 12.014917 | K30: 25 | L30: =IF(ISERROR(VLOOKUP(K30,Key!$A$2:$B$982,2,FALSE)),"",VLOOKUP(K30,Key!$A$2:$B$982,2,FALSE)) | M30: 25 | N30: =(ROUND((M30-0.5)/233*809+0.5,0)-0.5)/809*Calculator!$AD$2 | O30: 25 | P30: =IF(ISERROR(VLOOKUP(O30,Key!$A$2:$B$982,2,FALSE)),"",VLOOKUP(O30,Key!$A$2:$B$982,2,FALSE))
D31: =IF(ISERROR(VLOOKUP(C31,Key!$A$2:$B$982,2,FALSE)),"",VLOOKUP(C31,Key!$A$2:$B$982,2,FALSE)) | H31: =IF(ISERROR(VLOOKUP(G31,Key!$A$2:$B$982,2,FALSE)),"",VLOOKUP(G31,Key!$A$2:$B$982,2,FALSE)) | I31: 6.6 | J31: 12.436493 | K31: 26 | L31: =IF(ISERROR(VLOOKUP(K31,Key!$A$2:$B$982,2,FALSE)),"",VLOOKUP(K31,Key!$A$2:$B$982,2,FALSE)) | M31: 26 | N31: =(ROUND((M31-0.5)/233*809+0.5,0)-0.5)/809*Calculator!$AD$2 | O31: 26 | P31: =IF(ISERROR(VLOOKUP(O31,Key!$A$2:$B$982,2,FALSE)),"",VLOOKUP(O31,Key!$A$2:$B$982,2,FALSE))
D32: =IF(ISERROR(VLOOKUP(C32,Key!$A$2:$B$982,2,FALSE)),"",VLOOKUP(C32,Key!$A$2:$B$982,2,FALSE)) | H32: =IF(ISERROR(VLOOKUP(G32,Key!$A$2:$B$982,2,FALSE)),"",VLOOKUP(G32,Key!$A$2:$B$982,2,FALSE)) | L32: =IF(ISERROR(VLOOKUP(K32,Key!$A$2:$B$982,2,FALSE)),"",VLOOKUP(K32,Key!$A$2:$B$982,2,FALSE)) | M32: 27 | N32: =(ROUND((M32-0.5)/233*809+0.5,0)-0.5)/809*Calculator!$AD$2 | O32: 27 | P32: =IF(ISERROR(VLOOKUP(O32,Key!$A$2:$B$982,2,FALSE)),"",VLOOKUP(O32,Key!$A$2:$B$982,2,FALSE))
A33: 3 | B33: 13.420171 | C33: 30 | D33: =IF(ISERROR(VLOOKUP(C33,Key!$A$2:$B$982,2,FALSE)),"",VLOOKUP(C33,Key!$A$2:$B$982,2,FALSE)) | E33: 6 | F33: 13.420171 | G33: 30 | H33: =IF(ISERROR(VLOOKUP(G33,Key!$A$2:$B$982,2,FALSE)),"",VLOOKUP(G33,Key!$A$2:$B$982,2,FALSE)) | I33: 7 | J33: 13.420171 | K33: 30 | L33: =IF(ISERROR(VLOOKUP(K33,Key!$A$2:$B$982,2,FALSE)),"",VLOOKUP(K33,Key!$A$2:$B$982,2,FALSE)) | M33: 28 | N33: =(ROUND((M33-0.5)/233*809+0.5,0)-0.5)/809*Calculator!$AD$2 | O33: 28 | P33: =IF(ISERROR(VLOOKUP(O33,Key!$A$2:$B$982,2,FALSE)),"",VLOOKUP(O33,Key!$A$2:$B$982,2,FALSE))
D34: =IF(ISERROR(VLOOKUP(C34,Key!$A$2:$B$982,2,FALSE)),"",VLOOKUP(C34,Key!$A$2:$B$982,2,FALSE)) | H34: =IF(ISERROR(VLOOKUP(G34,Key!$A$2:$B$982,2,FALSE)),"",VLOOKUP(G34,Key!$A$2:$B$982,2,FALSE)) | L34: =IF(ISERROR(VLOOKUP(K34,Key!$A$2:$B$982,2,FALSE)),"",VLOOKUP(K34,Key!$A$2:$B$982,2,FALSE)) | M34: 29 | N34: =(ROUND((M34-0.5)/233*809+0.5,0)-0.5)/809*Calculator!$AD$2 | O34: 29 | P34: =IF(ISERROR(VLOOKUP(O34,Key!$A$2:$B$982,2,FALSE)),"",VLOOKUP(O34,Key!$A$2:$B$982,2,FALSE))
D35: =IF(ISERROR(VLOOKUP(C35,Key!$A$2:$B$982,2,FALSE)),"",VLOOKUP(C35,Key!$A$2:$B$982,2,FALSE)) | H35: =IF(ISERROR(VLOOKUP(G35,Key!$A$2:$B$982,2,FALSE)),"",VLOOKUP(G35,Key!$A$2:$B$982,2,FALSE)) | L35: =IF(ISERROR(VLOOKUP(K35,Key!$A$2:$B$982,2,FALSE)),"",VLOOKUP(K35,Key!$A$2:$B$982,2,FALSE)) | M35: 30 | N35: =(ROUND((M35-0.5)/233*809+0.5,0)-0.5)/809*Calculator!$AD$2 | O35: 30 | P35: =IF(ISERROR(VLOOKUP(O35,Key!$A$2:$B$982,2,FALSE)),"",VLOOKUP(O35,Key!$A$2:$B$982,2,FALSE))
D36: =IF(ISERROR(VLOOKUP(C36,Key!$A$2:$B$982,2,FALSE)),"",VLOOKUP(C36,Key!$A$2:$B$982,2,FALSE)) | H36: =IF(ISERROR(VLOOKUP(G36,Key!$A$2:$B$982,2,FALSE)),"",VLOOKUP(G36,Key!$A$2:$B$982,2,FALSE)) | L36: =IF(ISERROR(VLOOKUP(K36,Key!$A$2:$B$982,2,FALSE)),"",VLOOKUP(K36,Key!$A$2:$B$982,2,FALSE)) | M36: 31 | N36: =(ROUND((M36-0.5)/233*809+0.5,0)-0.5)/809*Calculator!$AD$2 | O36: 31 | P36: =IF(ISERROR(VLOOKUP(O36,Key!$A$2:$B$982,2,FALSE)),"",VLOOKUP(O36,Key!$A$2:$B$982,2,FALSE))
D37: =IF(ISERROR(VLOOKUP(C37,Key!$A$2:$B$982,2,FALSE)),"",VLOOKUP(C37,Key!$A$2:$B$982,2,FALSE)) | E37: 7 | F37: 15.387526 | G37: 34 | H37: =IF(ISERROR(VLOOKUP(G37,Key!$A$2:$B$982,2,FALSE)),"",VLOOKUP(G37,Key!$A$2:$B$982,2,FALSE)) | I37: 8 | J37: 15.387526 | K37: 34 | L37: =IF(ISERROR(VLOOKUP(K37,Key!$A$2:$B$982,2,FALSE)),"",VLOOKUP(K37,Key!$A$2:$B$982,2,FALSE)) | M37: 32 | N37: =(ROUND((M37-0.5)/233*809+0.5,0)-0.5)/809*Calculator!$AD$2 | O37: 32 | P37: =IF(ISERROR(VLOOKUP(O37,Key!$A$2:$B$982,2,FALSE)),"",VLOOKUP(O37,Key!$A$2:$B$982,2,FALSE))
D38: =IF(ISERROR(VLOOKUP(C38,Key!$A$2:$B$982,2,FALSE)),"",VLOOKUP(C38,Key!$A$2:$B$982,2,FALSE)) | H38: =IF(ISERROR(VLOOKUP(G38,Key!$A$2:$B$982,2,FALSE)),"",VLOOKUP(G38,Key!$A$2:$B$982,2,FALSE)) | L38: =IF(ISERROR(VLOOKUP(K38,Key!$A$2:$B$982,2,FALSE)),"",VLOOKUP(K38,Key!$A$2:$B$982,2,FALSE)) | M38: 33 | N38: =(ROUND((M38-0.5)/233*809+0.5,0)-0.5)/809*Calculator!$AD$2 | O38: 33 | P38: =IF(ISERROR(VLOOKUP(O38,Key!$A$2:$B$982,2,FALSE)),"",VLOOKUP(O38,Key!$A$2:$B$982,2,FALSE))
D39: =IF(ISERROR(VLOOKUP(C39,Key!$A$2:$B$982,2,FALSE)),"",VLOOKUP(C39,Key!$A$2:$B$982,2,FALSE)) | H39: =IF(ISERROR(VLOOKUP(G39,Key!$A$2:$B$982,2,FALSE)),"",VLOOKUP(G39,Key!$A$2:$B$982,2,FALSE)) | L39: =IF(ISERROR(VLOOKUP(K39,Key!$A$2:$B$982,2,FALSE)),"",VLOOKUP(K39,Key!$A$2:$B$982,2,FALSE)) | M39: 34 | N39: =(ROUND((M39-0.5)/233*809+0.5,0)-0.5)/809*Calculator!$AD$2 | O39: 34 | P39: =IF(ISERROR(VLOOKUP(O39,Key!$A$2:$B$982,2,FALSE)),"",VLOOKUP(O39,Key!$A$2:$B$982,2,FALSE))
D40: =IF(ISERROR(VLOOKUP(C40,Key!$A$2:$B$982,2,FALSE)),"",VLOOKUP(C40,Key!$A$2:$B$982,2,FALSE)) | H40: =IF(ISERROR(VLOOKUP(G40,Key!$A$2:$B$982,2,FALSE)),"",VLOOKUP(G40,Key!$A$2:$B$982,2,FALSE)) | L40: =IF(ISERROR(VLOOKUP(K40,Key!$A$2:$B$982,2,FALSE)),"",VLOOKUP(K40,Key!$A$2:$B$982,2,FALSE)) | M40: 35 | N40: =(ROUND((M40-0.5)/233*809+0.5,0)-0.5)/809*Calculator!$AD$2 | O40: 35 | P40: =IF(ISERROR(VLOOKUP(O40,Key!$A$2:$B$982,2,FALSE)),"",VLOOKUP(O40,Key!$A$2:$B$982,2,FALSE))
...

Sheet Commas
A1: Key | B1: Name | C1: Denominator | D1: Numerator | E1: Value (¢) | F1: Symbol
A2: 0 | B2: 1u | C2: 1 | D2: 1 | E2: =1200*LN($D2/$C2)/LN(2)
A3: 1 | B3: 1/455n | C3: 4095 | D3: 4096 | E3: =1200*LN($D3/$C3)/LN(2) | F3: =VLOOKUP(A3,Key!$A$2:$B$982,2,FALSE)
A4: 2 | B4: 65/77n | C4: 2079 | D4: 2080 | E4: =1200*LN($D4/$C4)/LN(2) | F4: =VLOOKUP(A4,Key!$A$2:$B$982,2,FALSE)
A5: 3 | B5: 19/5n | C5: 1215 | D5: 1216 | E5: =1200*LN($D5/$C5)/LN(2) | F5: =VLOOKUP(A5,Key!$A$2:$B$982,2,FALSE)
A6: 4 | B6: 5s | C6: 32768 | D6: 32805 | E6: =1200*LN($D6/$C6)/LN(2) | F6: =VLOOKUP(A6,Key!$A$2:$B$982,2,FALSE)
A7: 5 | B7: 1/91s | C7: 728 | D7: 729 | E7: =1200*LN($D7/$C7)/LN(2) | F7: =VLOOKUP(A7,Key!$A$2:$B$982,2,FALSE)
A8: 6 | B8: 19/4375s | C8: 1120000 | D8: 1121931 | E8: =1200*LN($D8/$C8)/LN(2) | F8: =VLOOKUP(A8,Key!$A$2:$B$982,2,FALSE)
A9: 7 | B9: 19s | C9: 512 | D9: 513 | E9: =1200*LN($D9/$C9)/LN(2) | F9: =VLOOKUP(A9,Key!$A$2:$B$982,2,FALSE)
A10: 8 | B10: 49/55s | C10: 440 | D10: 441 | E10: =1200*LN($D10/$C10)/LN(2) | F10: =VLOOKUP(A10,Key!$A$2:$B$982,2,FALSE)
A11: 9 | B11: 385k | C11: 384 | D11: 385 | E11: =1200*LN($D11/$C11)/LN(2) | F11: =VLOOKUP(A11,Key!$A$2:$B$982,2,FALSE)
A12: 10 | B12: 11/13k | C12: 351 | D12: 352 | E12: =1200*LN($D12/$C12)/LN(2) | F12: =VLOOKUP(A12,Key!$A$2:$B$982,2,FALSE)
A13: 11 | B13: 31/11k | C13: 22528 | D13: 22599 | E13: =1200*LN($D13/$C13)/LN(2) | F13: =VLOOKUP(A13,Key!$A$2:$B$982,2,FALSE)
A14: 12 | B14: 5/7k | C14: 5103 | D14: 5120 | E14: =1200*LN($D14/$C14)/LN(2) | F14: =VLOOKUP(A14,Key!$A$2:$B$982,2,FALSE)
... A149: 147 | B149: 13/25L | C149: 25 | D149: 26 | E149: =1200*LN($D149/$C149)/LN(2) | F149: =VLOOKUP(A149,Key!$A$2:$B$982,2,FALSE)
A150: 148 | B150: 25/77L | C150: 164025 | D150: 157696 | E150: 68.123586 | F150: ``)|\\

Sheet Key
A1: Key | B1: Mixed Symbol | C1: Pure Symbol | D1: Mixed Unicode | E1: Pure Unicode
A2: 0
A3: 1 | B3: `| | C3: `| | D3:   | E3:  
A4: 2 | B4: ``| | C4: ``| | D4:   | E4:  
A5: 3 | B5: .)| | C5: .)| | D5:   | E5:  
A6: 4 | B6: '| | C6: '| | D6:   | E6:  
A7: 5 | B7: `'| | C7: `'| | D7:    | E7:   
A8: 6 | B8: ,)| | C8: ,)| | D8:   | E8:  
A9: 7 | B9: )| | C9: )| | D9:  | E9: 
A10: 8 | B10: `)| | C10: `)| | D10:   | E10:  
A11: 9 | B11: ``)| | C11: ``)| | D11:   | E11:  
A12: 10 | B12: ,,|( | C12: ,,|( | D12:   | E12:  
A13: 11 | B13: ,|( | C13: ,|( | D13:   | E13:  
A14: 12 | B14: |( | C14: |( | D14:  | E14: 
... A982: -1904 | B982: '//|bb | C982: ')Y( | D982:    | E982:  
